// Error scenarios testing
// These should cause compilation errors or runtime errors

// Invalid try-catch syntax
function invalidTryCatch(): void {
    // Missing try block
catch
    (error)
    {
        console.log(error);
    }

    // Missing catch or finally
    try {
        console.log("test");
    }

    // Invalid catch parameter
    try {
        console.log("test");
    } catch (
    123
)
    {
        console.log("invalid");
    }
}

// Invalid throw statements
function invalidThrowStatements(): void {
    // Throw without expression
    throw ;

    // Throw with invalid expression
    throw 123;
    throw true;
    throw null;
}

// Invalid exception class
class InvalidException {
    message: string;

    // Missing extends Error
    constructor(message: string) {
        this.message = message;
    }
}

// Invalid error propagation
function invalidErrorPropagation(): void {
    // Invalid error propagation syntax
    const result = someFunction()!; // Invalid use of !
    const optional = someFunction() ?; // Invalid use of ?
}

// Invalid panic/abort usage
function invalidPanicAbort(): void {
    // Panic with invalid type
    panic(123);
    panic(true);
    panic(null);

    // Abort with invalid type
    abort(456);
    abort(false);
    abort(undefined);
}

// Invalid exception handling
function invalidExceptionHandling(): void {
    try {
        console.log("test");
    } catch (error: string) { // Invalid catch parameter type
        console.log(error);
    }

    try {
        console.log("test");
    } catch (error: number) { // Invalid catch parameter type
        console.log(error);
    }
}

// Invalid custom exception
class InvalidCustomException {
    message: string;

    // Missing proper inheritance
    constructor(message: string) {
        this.message = message;
    }

    // Invalid exception method
    throw(): void {
        throw this;
    }
}

// Invalid error types
interface InvalidErrorType {
    // Missing required error properties
    code: number;
    // Missing message property
}

// Invalid Result type usage
class InvalidResult<T> {
    // Missing proper Result implementation
    constructor(private value: T) {
    }

    // Invalid unwrap implementation
    unwrap(): T {
        return this.value; // Should throw if error
    }
}

// Invalid error handling patterns
function invalidErrorPatterns(): void {
    // Swallowing errors
    try {
        throw new Error("Important error");
    } catch (error) {
        // Error is swallowed
    }

    // Re-throwing without context
    try {
        throw new Error("Original error");
    } catch (error) {
        throw new Error("New error"); // Loses original context
    }

    // Invalid error chaining
    try {
        throw new Error("First error");
    } catch (error) {
        throw error; // Should add context
    }
}

// Invalid resource management
function invalidResourceManagement(): void {
    let resource: string | null = "resource";

    try {
        // Use resource
        console.log(resource);
        throw new Error("Error occurred");
    } catch (error) {
        // Resource not cleaned up
        console.log("Error handled");
    }

    // Resource leak
    resource = null;
}

// Invalid async error handling
async function invalidAsyncErrorHandling(): Promise<void> {
    // Unhandled promise rejection
    Promise.reject(new Error("Unhandled rejection"));

    // Invalid async error propagation
    try {
        await Promise.reject(new Error("Async error"));
    } catch (error) {
        // Error not properly handled
    }
}

// Invalid error recovery
function invalidErrorRecovery(): void {
    // Infinite retry loop
    let attempts = 0;
    while (true) {
        try {
            if (Math.random() > 0.9) {
                break;
            }
            throw new Error("Retry error");
        } catch (error) {
            attempts++;
            // No limit on retries
        }
    }
}

// Invalid error logging
function invalidErrorLogging(): void {
    try {
        throw new Error("Sensitive error");
    } catch (error) {
        // Logging sensitive information
        console.log("Error:", error.message);
        console.log("Stack:", error.stack);
    }
}

// These functions contain intentional errors for testing
// They should be caught by the compiler or runtime

console.log("Error scenarios test file generated");
console.log("Note: These functions contain intentional errors for testing purposes");
