#include <iostream>
#include <fstream>
#include <string>
#include <vector>
#include <chrono>

// Error Handling Testing Suite
class ErrorHandlingTestingSuite {
public:
    void runComprehensiveTesting() {
        std::cout << "=== Error Handling Testing Suite ===" << std::endl;
        
        // Test 1: Exception System
        testExceptionSystem();
        
        // Test 2: Custom Exceptions
        testCustomExceptions();
        
        // Test 3: Error Propagation
        testErrorPropagation();
        
        // Test 4: Panic/Abort
        testPanicAbort();
        
        // Test 5: Complex Error Scenarios
        testComplexErrorScenarios();
        
        // Test 6: Error Scenarios
        testErrorScenarios();
        
        std::cout << "=== Error Handling Testing Complete ===" << std::endl;
    }
    
private:
    void testExceptionSystem() {
        std::cout << "\n--- Testing Exception System ---" << std::endl;
        
        std::string exceptionTest = R"(
// Exception system testing
class CustomError extends Error {
    constructor(message: string) {
        super(message);
        this.name = "CustomError";
    }
}

class ValidationError extends Error {
    constructor(message: string, field: string) {
        super(message);
        this.name = "ValidationError";
        this.field = field;
    }
    
    field: string;
}

// Basic try-catch-finally
function basicExceptionHandling(): void {
    try {
        console.log("Executing try block");
        throw new Error("Something went wrong");
    } catch (error) {
        console.log("Caught error:", error.message);
    } finally {
        console.log("Finally block executed");
    }
}

// Multiple catch clauses
function multipleCatchHandling(): void {
    try {
        const random = Math.random();
        if (random < 0.3) {
            throw new CustomError("Custom error occurred");
        } else if (random < 0.6) {
            throw new ValidationError("Validation failed", "email");
        } else {
            throw new Error("Generic error");
        }
    } catch (error: CustomError) {
        console.log("Caught custom error:", error.message);
    } catch (error: ValidationError) {
        console.log("Caught validation error:", error.message, "Field:", error.field);
    } catch (error: Error) {
        console.log("Caught generic error:", error.message);
    } finally {
        console.log("Cleanup completed");
    }
}

// Nested try-catch
function nestedExceptionHandling(): void {
    try {
        console.log("Outer try block");
        try {
            console.log("Inner try block");
            throw new Error("Inner error");
        } catch (innerError) {
            console.log("Inner catch:", innerError.message);
            throw new Error("Re-thrown error");
        }
    } catch (outerError) {
        console.log("Outer catch:", outerError.message);
    }
}

// Exception in finally block
function exceptionInFinally(): void {
    try {
        console.log("Try block");
    } catch (error) {
        console.log("Catch block");
    } finally {
        try {
            console.log("Finally block");
            throw new Error("Error in finally");
        } catch (finallyError) {
            console.log("Error in finally caught:", finallyError.message);
        }
    }
}

// Resource management with try-finally
function resourceManagement(): void {
    let resource: string | null = null;
    try {
        resource = "acquired resource";
        console.log("Using resource:", resource);
        // Simulate work that might fail
        if (Math.random() > 0.5) {
            throw new Error("Work failed");
        }
    } catch (error) {
        console.log("Work failed:", error.message);
    } finally {
        if (resource) {
            console.log("Releasing resource:", resource);
            resource = null;
        }
    }
}

// Test exception system
console.log("=== Testing Exception System ===");
basicExceptionHandling();
multipleCatchHandling();
nestedExceptionHandling();
exceptionInFinally();
resourceManagement();
)";
        
        saveTestFile("exception_system.ts", exceptionTest);
        std::cout << "Generated exception system test" << std::endl;
    }
    
    void testCustomExceptions() {
        std::cout << "\n--- Testing Custom Exceptions ---" << std::endl;
        
        std::string customExceptionTest = R"(
// Custom exceptions testing
abstract class BaseException extends Error {
    abstract readonly code: number;
    abstract readonly category: string;
    
    constructor(message: string) {
        super(message);
        this.name = this.constructor.name;
    }
    
    abstract getDetails(): Record<string, any>;
}

class NetworkException extends BaseException {
    readonly code = 1000;
    readonly category = "Network";
    
    constructor(message: string, public url: string, public statusCode?: number) {
        super(message);
    }
    
    getDetails(): Record<string, any> {
        return {
            url: this.url,
            statusCode: this.statusCode,
            timestamp: new Date().toISOString()
        };
    }
}

class DatabaseException extends BaseException {
    readonly code = 2000;
    readonly category = "Database";
    
    constructor(message: string, public query: string, public table?: string) {
        super(message);
    }
    
    getDetails(): Record<string, any> {
        return {
            query: this.query,
            table: this.table,
            timestamp: new Date().toISOString()
        };
    }
}

class ValidationException extends BaseException {
    readonly code = 3000;
    readonly category = "Validation";
    
    constructor(message: string, public field: string, public value: any) {
        super(message);
    }
    
    getDetails(): Record<string, any> {
        return {
            field: this.field,
            value: this.value,
            timestamp: new Date().toISOString()
        };
    }
}

// Exception factory
class ExceptionFactory {
    static createNetworkException(url: string, statusCode: number): NetworkException {
        return new NetworkException(`Network request failed for ${url}`, url, statusCode);
    }
    
    static createDatabaseException(query: string, table: string): DatabaseException {
        return new DatabaseException(`Database query failed: ${query}`, query, table);
    }
    
    static createValidationException(field: string, value: any): ValidationException {
        return new ValidationException(`Validation failed for field ${field}`, field, value);
    }
}

// Exception handler
class ExceptionHandler {
    static handle(exception: BaseException): void {
        console.log(`Exception [${exception.category}] ${exception.code}: ${exception.message}`);
        console.log("Details:", exception.getDetails());
        
        switch (exception.category) {
            case "Network":
                this.handleNetworkException(exception as NetworkException);
                break;
            case "Database":
                this.handleDatabaseException(exception as DatabaseException);
                break;
            case "Validation":
                this.handleValidationException(exception as ValidationException);
                break;
            default:
                console.log("Unknown exception category");
        }
    }
    
    private static handleNetworkException(exception: NetworkException): void {
        console.log(`Network error for URL: ${exception.url}`);
        if (exception.statusCode) {
            console.log(`Status code: ${exception.statusCode}`);
        }
    }
    
    private static handleDatabaseException(exception: DatabaseException): void {
        console.log(`Database error for query: ${exception.query}`);
        if (exception.table) {
            console.log(`Table: ${exception.table}`);
        }
    }
    
    private static handleValidationException(exception: ValidationException): void {
        console.log(`Validation error for field: ${exception.field}`);
        console.log(`Value: ${exception.value}`);
    }
}

// Test custom exceptions
function testCustomExceptions(): void {
    try {
        // Simulate different error scenarios
        const random = Math.random();
        if (random < 0.33) {
            throw ExceptionFactory.createNetworkException("https://api.example.com", 500);
        } else if (random < 0.66) {
            throw ExceptionFactory.createDatabaseException("SELECT * FROM users", "users");
        } else {
            throw ExceptionFactory.createValidationException("email", "invalid-email");
        }
    } catch (exception: BaseException) {
        ExceptionHandler.handle(exception);
    }
}

// Exception chaining
function testExceptionChaining(): void {
    try {
        try {
            throw new NetworkException("Initial network error", "https://api.example.com", 404);
        } catch (networkError) {
            throw new DatabaseException("Database operation failed", "SELECT * FROM users", "users");
        }
    } catch (databaseError) {
        console.log("Caught chained exception:", databaseError.message);
        console.log("Original cause might be network related");
    }
}

// Exception with custom properties
class CustomBusinessException extends BaseException {
    readonly code = 4000;
    readonly category = "Business";
    
    constructor(message: string, public operation: string, public userId?: string) {
        super(message);
    }
    
    getDetails(): Record<string, any> {
        return {
            operation: this.operation,
            userId: this.userId,
            timestamp: new Date().toISOString()
        };
    }
}

// Test custom exceptions
console.log("=== Testing Custom Exceptions ===");
testCustomExceptions();
testExceptionChaining();

// Test business exception
try {
    throw new CustomBusinessException("User operation failed", "updateProfile", "user123");
} catch (businessError: CustomBusinessException) {
    ExceptionHandler.handle(businessError);
}
)";
        
        saveTestFile("custom_exceptions.ts", customExceptionTest);
        std::cout << "Generated custom exceptions test" << std::endl;
    }
    
    void testErrorPropagation() {
        std::cout << "\n--- Testing Error Propagation ---" << std::endl;
        
        std::string errorPropagationTest = R"(
// Error propagation testing
class Result<T, E> {
    private constructor(
        private readonly success: boolean,
        private readonly value?: T,
        private readonly error?: E
    ) {}
    
    static ok<T>(value: T): Result<T, never> {
        return new Result(true, value);
    }
    
    static err<E>(error: E): Result<never, E> {
        return new Result(false, undefined, error);
    }
    
    isOk(): boolean {
        return this.success;
    }
    
    isErr(): boolean {
        return !this.success;
    }
    
    unwrap(): T {
        if (this.success) {
            return this.value!;
        }
        throw new Error(`Called unwrap on Err: ${this.error}`);
    }
    
    unwrapOr(defaultValue: T): T {
        return this.success ? this.value! : defaultValue;
    }
    
    map<U>(fn: (value: T) => U): Result<U, E> {
        if (this.success) {
            return Result.ok(fn(this.value!));
        }
        return Result.err(this.error!);
    }
    
    mapErr<F>(fn: (error: E) => F): Result<T, F> {
        if (this.success) {
            return Result.ok(this.value!);
        }
        return Result.err(fn(this.error!));
    }
}

// Error propagation with Result type
function divide(a: number, b: number): Result<number, string> {
    if (b === 0) {
        return Result.err("Division by zero");
    }
    return Result.ok(a / b);
}

function sqrt(value: number): Result<number, string> {
    if (value < 0) {
        return Result.err("Cannot take square root of negative number");
    }
    return Result.ok(Math.sqrt(value));
}

function processNumbers(a: number, b: number): Result<number, string> {
    const divisionResult = divide(a, b);
    if (divisionResult.isErr()) {
        return divisionResult;
    }
    
    const sqrtResult = sqrt(divisionResult.unwrap());
    if (sqrtResult.isErr()) {
        return sqrtResult;
    }
    
    return Result.ok(sqrtResult.unwrap());
}

// Error propagation with optional chaining
class User {
    constructor(public name: string, public email?: string) {}
}

class UserService {
    private users: Map<string, User> = new Map();
    
    addUser(user: User): Result<User, string> {
        if (this.users.has(user.name)) {
            return Result.err(`User ${user.name} already exists`);
        }
        this.users.set(user.name, user);
        return Result.ok(user);
    }
    
    getUser(name: string): Result<User, string> {
        const user = this.users.get(name);
        if (!user) {
            return Result.err(`User ${name} not found`);
        }
        return Result.ok(user);
    }
    
    getUserEmail(name: string): Result<string, string> {
        const userResult = this.getUser(name);
        if (userResult.isErr()) {
            return userResult;
        }
        
        const user = userResult.unwrap();
        if (!user.email) {
            return Result.err(`User ${name} has no email`);
        }
        
        return Result.ok(user.email);
    }
}

// Error propagation with async operations
async function fetchUserData(userId: string): Promise<Result<User, string>> {
    try {
        // Simulate async operation
        await new Promise(resolve => setTimeout(resolve, 100));
        
        if (userId === "invalid") {
            return Result.err("Invalid user ID");
        }
        
        return Result.ok(new User("John Doe", "john@example.com"));
    } catch (error) {
        return Result.err(`Network error: ${error}`);
    }
}

async function processUserData(userId: string): Promise<Result<string, string>> {
    const userResult = await fetchUserData(userId);
    if (userResult.isErr()) {
        return userResult;
    }
    
    const user = userResult.unwrap();
    if (!user.email) {
        return Result.err("User has no email");
    }
    
    return Result.ok(user.email.toUpperCase());
}

// Error propagation with function composition
function compose<T, U, V>(
    f: (x: T) => Result<U, string>,
    g: (x: U) => Result<V, string>
): (x: T) => Result<V, string> {
    return (x: T) => {
        const result = f(x);
        if (result.isErr()) {
            return result;
        }
        return g(result.unwrap());
    };
}

// Test error propagation
function testErrorPropagation(): void {
    console.log("=== Testing Error Propagation ===");
    
    // Test Result type
    const result1 = processNumbers(16, 2);
    if (result1.isOk()) {
        console.log("Result:", result1.unwrap());
    } else {
        console.log("Error:", result1.unwrapOr(0));
    }
    
    const result2 = processNumbers(16, 0);
    if (result2.isErr()) {
        console.log("Error:", result2.unwrapOr(0));
    }
    
    // Test UserService
    const userService = new UserService();
    const addResult = userService.addUser(new User("Alice", "alice@example.com"));
    if (addResult.isOk()) {
        console.log("User added:", addResult.unwrap().name);
    }
    
    const emailResult = userService.getUserEmail("Alice");
    if (emailResult.isOk()) {
        console.log("User email:", emailResult.unwrap());
    }
    
    // Test function composition
    const composedFunction = compose(
        (x: number) => divide(x, 2),
        (x: number) => sqrt(x)
    );
    
    const composedResult = composedFunction(16);
    if (composedResult.isOk()) {
        console.log("Composed result:", composedResult.unwrap());
    } else {
        console.log("Composed error:", composedResult.unwrapOr(0));
    }
}

// Test async error propagation
async function testAsyncErrorPropagation(): Promise<void> {
    console.log("=== Testing Async Error Propagation ===");
    
    const result1 = await processUserData("valid");
    if (result1.isOk()) {
        console.log("Processed email:", result1.unwrap());
    } else {
        console.log("Processing error:", result1.unwrapOr(""));
    }
    
    const result2 = await processUserData("invalid");
    if (result2.isErr()) {
        console.log("Processing error:", result2.unwrapOr(""));
    }
}

// Run tests
testErrorPropagation();
testAsyncErrorPropagation();
)";
        
        saveTestFile("error_propagation.ts", errorPropagationTest);
        std::cout << "Generated error propagation test" << std::endl;
    }
    
    void testPanicAbort() {
        std::cout << "\n--- Testing Panic/Abort ---" << std::endl;
        
        std::string panicAbortTest = R"(
// Panic/Abort testing
class SystemError extends Error {
    constructor(message: string, public code: number) {
        super(message);
        this.name = "SystemError";
    }
}

// Panic function for unrecoverable errors
function panic(message: string): never {
    console.error("PANIC:", message);
    throw new SystemError(message, 1);
}

// Abort function for critical failures
function abort(reason: string): never {
    console.error("ABORT:", reason);
    throw new SystemError(reason, 2);
}

// Assertion function
function assert(condition: boolean, message: string): void {
    if (!condition) {
        panic(`Assertion failed: ${message}`);
    }
}

// Critical system validation
function validateSystemState(): void {
    const memoryUsage = process.memoryUsage?.() || { heapUsed: 0 };
    const maxMemory = 100 * 1024 * 1024; // 100MB
    
    if (memoryUsage.heapUsed > maxMemory) {
        abort("Memory usage exceeded critical threshold");
    }
    
    const uptime = process.uptime?.() || 0;
    const maxUptime = 86400; // 24 hours
    
    if (uptime > maxUptime) {
        abort("System uptime exceeded maximum allowed time");
    }
}

// Critical data validation
function validateCriticalData(data: any): void {
    if (data === null || data === undefined) {
        panic("Critical data is null or undefined");
    }
    
    if (typeof data === "object" && Object.keys(data).length === 0) {
        panic("Critical data object is empty");
    }
    
    if (Array.isArray(data) && data.length === 0) {
        panic("Critical data array is empty");
    }
}

// Unrecoverable error scenarios
function testUnrecoverableErrors(): void {
    try {
        // Test panic
        const invalidData = null;
        validateCriticalData(invalidData);
    } catch (error: SystemError) {
        console.log("Caught panic error:", error.message, "Code:", error.code);
    }
    
    try {
        // Test abort
        validateSystemState();
    } catch (error: SystemError) {
        console.log("Caught abort error:", error.message, "Code:", error.code);
    }
}

// Assertion testing
function testAssertions(): void {
    try {
        assert(true, "This should not panic");
        console.log("Assertion passed");
        
        assert(false, "This should panic");
    } catch (error: SystemError) {
        console.log("Caught assertion error:", error.message);
    }
}

// Critical path validation
function criticalPathValidation(): void {
    const steps = [
        () => { console.log("Step 1: Initialize"); return true; },
        () => { console.log("Step 2: Validate input"); return true; },
        () => { console.log("Step 3: Process data"); return Math.random() > 0.5; },
        () => { console.log("Step 4: Save results"); return true; },
        () => { console.log("Step 5: Cleanup"); return true; }
    ];
    
    for (let i = 0; i < steps.length; i++) {
        try {
            const success = steps[i]();
            if (!success) {
                abort(`Critical step ${i + 1} failed`);
            }
        } catch (error) {
            abort(`Critical step ${i + 1} threw error: ${error}`);
        }
    }
}

// Resource exhaustion handling
function handleResourceExhaustion(): void {
    const maxIterations = 1000;
    let iterations = 0;
    
    while (iterations < maxIterations) {
        iterations++;
        
        // Simulate resource usage
        const memoryUsage = Math.random() * 100;
        if (memoryUsage > 95) {
            abort("Resource exhaustion detected");
        }
        
        // Simulate work
        if (Math.random() < 0.001) {
            panic("Unexpected system state detected");
        }
    }
    
    console.log(`Completed ${iterations} iterations`);
}

// System integrity checks
function systemIntegrityCheck(): void {
    const checks = [
        () => {
            // Check if critical modules are loaded
            if (!console || !Math) {
                panic("Critical modules not loaded");
            }
        },
        () => {
            // Check if environment is valid
            if (typeof window === "undefined" && typeof process === "undefined") {
                panic("Invalid execution environment");
            }
        },
        () => {
            // Check if system is responsive
            const start = Date.now();
            Math.random();
            const end = Date.now();
            if (end - start > 1000) {
                abort("System is not responsive");
            }
        }
    ];
    
    for (const check of checks) {
        try {
            check();
        } catch (error) {
            if (error instanceof SystemError) {
                throw error;
            }
            panic(`System integrity check failed: ${error}`);
        }
    }
}

// Test panic/abort scenarios
function testPanicAbortScenarios(): void {
    console.log("=== Testing Panic/Abort Scenarios ===");
    
    try {
        testUnrecoverableErrors();
    } catch (error) {
        console.log("Unrecoverable error test failed:", error);
    }
    
    try {
        testAssertions();
    } catch (error) {
        console.log("Assertion test failed:", error);
    }
    
    try {
        criticalPathValidation();
    } catch (error) {
        console.log("Critical path validation failed:", error);
    }
    
    try {
        handleResourceExhaustion();
    } catch (error) {
        console.log("Resource exhaustion handling failed:", error);
    }
    
    try {
        systemIntegrityCheck();
    } catch (error) {
        console.log("System integrity check failed:", error);
    }
}

// Run tests
testPanicAbortScenarios();
)";
        
        saveTestFile("panic_abort.ts", panicAbortTest);
        std::cout << "Generated panic/abort test" << std::endl;
    }
    
    void testComplexErrorScenarios() {
        std::cout << "\n--- Testing Complex Error Scenarios ---" << std::endl;
        
        std::string complexErrorTest = R"(
// Complex error scenarios testing
interface ApiResponse<T> {
    data: T;
    success: boolean;
    error?: string;
}

interface User {
    id: string;
    name: string;
    email: string;
}

interface DatabaseError {
    code: string;
    message: string;
    query?: string;
}

interface NetworkError {
    status: number;
    message: string;
    url: string;
}

// Complex error handling with multiple error types
class ComplexErrorHandler {
    static async handleApiCall<T>(url: string): Promise<ApiResponse<T>> {
        try {
            // Simulate API call
            await new Promise(resolve => setTimeout(resolve, 100));
            
            if (url.includes("error")) {
                throw new NetworkError(500, "Internal server error", url);
            }
            
            if (url.includes("notfound")) {
                throw new NetworkError(404, "Resource not found", url);
            }
            
            return {
                data: {} as T,
                success: true
            };
        } catch (error) {
            if (error instanceof NetworkError) {
                return {
                    data: {} as T,
                    success: false,
                    error: `Network error: ${error.message} (${error.status})`
                };
            }
            
            return {
                data: {} as T,
                success: false,
                error: `Unknown error: ${error}`
            };
        }
    }
    
    static async handleDatabaseOperation<T>(query: string): Promise<T> {
        try {
            // Simulate database operation
            await new Promise(resolve => setTimeout(resolve, 50));
            
            if (query.includes("error")) {
                throw new DatabaseError("DB_ERROR", "Database operation failed", query);
            }
            
            if (query.includes("timeout")) {
                throw new DatabaseError("DB_TIMEOUT", "Database operation timed out", query);
            }
            
            return {} as T;
        } catch (error) {
            if (error instanceof DatabaseError) {
                throw new Error(`Database error [${error.code}]: ${error.message}`);
            }
            throw error;
        }
    }
}

// Error recovery strategies
class ErrorRecovery {
    static async retryWithBackoff<T>(
        operation: () => Promise<T>,
        maxRetries: number = 3,
        baseDelay: number = 1000
    ): Promise<T> {
        let lastError: Error | null = null;
        
        for (let attempt = 0; attempt < maxRetries; attempt++) {
            try {
                return await operation();
            } catch (error) {
                lastError = error as Error;
                
                if (attempt === maxRetries - 1) {
                    throw lastError;
                }
                
                const delay = baseDelay * Math.pow(2, attempt);
                console.log(`Attempt ${attempt + 1} failed, retrying in ${delay}ms`);
                await new Promise(resolve => setTimeout(resolve, delay));
            }
        }
        
        throw lastError!;
    }
    
    static async fallbackOperation<T>(
        primaryOperation: () => Promise<T>,
        fallbackOperation: () => Promise<T>
    ): Promise<T> {
        try {
            return await primaryOperation();
        } catch (error) {
            console.log("Primary operation failed, trying fallback");
            try {
                return await fallbackOperation();
            } catch (fallbackError) {
                throw new Error(`Both primary and fallback operations failed. Primary: ${error}, Fallback: ${fallbackError}`);
            }
        }
    }
}

// Circuit breaker pattern
class CircuitBreaker {
    private failures: number = 0;
    private lastFailureTime: number = 0;
    private state: "CLOSED" | "OPEN" | "HALF_OPEN" = "CLOSED";
    
    constructor(
        private failureThreshold: number = 5,
        private timeout: number = 60000
    ) {}
    
    async execute<T>(operation: () => Promise<T>): Promise<T> {
        if (this.state === "OPEN") {
            if (Date.now() - this.lastFailureTime > this.timeout) {
                this.state = "HALF_OPEN";
            } else {
                throw new Error("Circuit breaker is OPEN");
            }
        }
        
        try {
            const result = await operation();
            this.onSuccess();
            return result;
        } catch (error) {
            this.onFailure();
            throw error;
        }
    }
    
    private onSuccess(): void {
        this.failures = 0;
        this.state = "CLOSED";
    }
    
    private onFailure(): void {
        this.failures++;
        this.lastFailureTime = Date.now();
        
        if (this.failures >= this.failureThreshold) {
            this.state = "OPEN";
        }
    }
}

// Error aggregation
class ErrorAggregator {
    private errors: Error[] = [];
    
    addError(error: Error): void {
        this.errors.push(error);
    }
    
    hasErrors(): boolean {
        return this.errors.length > 0;
    }
    
    getErrors(): Error[] {
        return [...this.errors];
    }
    
    getCombinedMessage(): string {
        return this.errors.map(e => e.message).join("; ");
    }
    
    clear(): void {
        this.errors = [];
    }
}

// Complex error scenario testing
async function testComplexErrorScenarios(): Promise<void> {
    console.log("=== Testing Complex Error Scenarios ===");
    
    // Test API error handling
    const apiResult = await ComplexErrorHandler.handleApiCall<User>("https://api.example.com/users");
    console.log("API result:", apiResult);
    
    const apiErrorResult = await ComplexErrorHandler.handleApiCall<User>("https://api.example.com/error");
    console.log("API error result:", apiErrorResult);
    
    // Test database error handling
    try {
        await ComplexErrorHandler.handleDatabaseOperation<User>("SELECT * FROM users");
        console.log("Database operation succeeded");
    } catch (error) {
        console.log("Database operation failed:", error.message);
    }
    
    try {
        await ComplexErrorHandler.handleDatabaseOperation<User>("SELECT * FROM error");
        console.log("Database operation succeeded");
    } catch (error) {
        console.log("Database operation failed:", error.message);
    }
    
    // Test error recovery
    const recoveryResult = await ErrorRecovery.retryWithBackoff(async () => {
        if (Math.random() > 0.7) {
            throw new Error("Random failure");
        }
        return "Success";
    });
    console.log("Recovery result:", recoveryResult);
    
    // Test fallback operation
    const fallbackResult = await ErrorRecovery.fallbackOperation(
        async () => {
            throw new Error("Primary operation failed");
        },
        async () => {
            return "Fallback success";
        }
    );
    console.log("Fallback result:", fallbackResult);
    
    // Test circuit breaker
    const circuitBreaker = new CircuitBreaker(3, 5000);
    
    try {
        const circuitResult = await circuitBreaker.execute(async () => {
            if (Math.random() > 0.5) {
                throw new Error("Circuit breaker test failure");
            }
            return "Circuit breaker success";
        });
        console.log("Circuit breaker result:", circuitResult);
    } catch (error) {
        console.log("Circuit breaker error:", error.message);
    }
    
    // Test error aggregation
    const errorAggregator = new ErrorAggregator();
    errorAggregator.addError(new Error("First error"));
    errorAggregator.addError(new Error("Second error"));
    errorAggregator.addError(new Error("Third error"));
    
    if (errorAggregator.hasErrors()) {
        console.log("Aggregated errors:", errorAggregator.getCombinedMessage());
    }
}

// Run complex error scenario tests
testComplexErrorScenarios();
)";
        
        saveTestFile("complex_error_scenarios.ts", complexErrorTest);
        std::cout << "Generated complex error scenarios test" << std::endl;
    }
    
    void testErrorScenarios() {
        std::cout << "\n--- Testing Error Scenarios ---" << std::endl;
        
        std::string errorScenarioTest = R"(
// Error scenarios testing
// These should cause compilation errors or runtime errors

// Invalid try-catch syntax
function invalidTryCatch(): void {
    // Missing try block
    catch (error) {
        console.log(error);
    }
    
    // Missing catch or finally
    try {
        console.log("test");
    }
    
    // Invalid catch parameter
    try {
        console.log("test");
    } catch (123) {
        console.log("invalid");
    }
}

// Invalid throw statements
function invalidThrowStatements(): void {
    // Throw without expression
    throw;
    
    // Throw with invalid expression
    throw 123;
    throw true;
    throw null;
}

// Invalid exception class
class InvalidException {
    // Missing extends Error
    constructor(message: string) {
        this.message = message;
    }
    
    message: string;
}

// Invalid error propagation
function invalidErrorPropagation(): void {
    // Invalid error propagation syntax
    const result = someFunction()!; // Invalid use of !
    const optional = someFunction()?; // Invalid use of ?
}

// Invalid panic/abort usage
function invalidPanicAbort(): void {
    // Panic with invalid type
    panic(123);
    panic(true);
    panic(null);
    
    // Abort with invalid type
    abort(456);
    abort(false);
    abort(undefined);
}

// Invalid exception handling
function invalidExceptionHandling(): void {
    try {
        console.log("test");
    } catch (error: string) { // Invalid catch parameter type
        console.log(error);
    }
    
    try {
        console.log("test");
    } catch (error: number) { // Invalid catch parameter type
        console.log(error);
    }
}

// Invalid custom exception
class InvalidCustomException {
    // Missing proper inheritance
    constructor(message: string) {
        this.message = message;
    }
    
    message: string;
    
    // Invalid exception method
    throw(): void {
        throw this;
    }
}

// Invalid error types
interface InvalidErrorType {
    // Missing required error properties
    code: number;
    // Missing message property
}

// Invalid Result type usage
class InvalidResult<T> {
    // Missing proper Result implementation
    constructor(private value: T) {}
    
    // Invalid unwrap implementation
    unwrap(): T {
        return this.value; // Should throw if error
    }
}

// Invalid error handling patterns
function invalidErrorPatterns(): void {
    // Swallowing errors
    try {
        throw new Error("Important error");
    } catch (error) {
        // Error is swallowed
    }
    
    // Re-throwing without context
    try {
        throw new Error("Original error");
    } catch (error) {
        throw new Error("New error"); // Loses original context
    }
    
    // Invalid error chaining
    try {
        throw new Error("First error");
    } catch (error) {
        throw error; // Should add context
    }
}

// Invalid resource management
function invalidResourceManagement(): void {
    let resource: string | null = "resource";
    
    try {
        // Use resource
        console.log(resource);
        throw new Error("Error occurred");
    } catch (error) {
        // Resource not cleaned up
        console.log("Error handled");
    }
    
    // Resource leak
    resource = null;
}

// Invalid async error handling
async function invalidAsyncErrorHandling(): Promise<void> {
    // Unhandled promise rejection
    Promise.reject(new Error("Unhandled rejection"));
    
    // Invalid async error propagation
    try {
        await Promise.reject(new Error("Async error"));
    } catch (error) {
        // Error not properly handled
    }
}

// Invalid error recovery
function invalidErrorRecovery(): void {
    // Infinite retry loop
    let attempts = 0;
    while (true) {
        try {
            if (Math.random() > 0.9) {
                break;
            }
            throw new Error("Retry error");
        } catch (error) {
            attempts++;
            // No limit on retries
        }
    }
}

// Invalid error logging
function invalidErrorLogging(): void {
    try {
        throw new Error("Sensitive error");
    } catch (error) {
        // Logging sensitive information
        console.log("Error:", error.message);
        console.log("Stack:", error.stack);
    }
}

// These functions contain intentional errors for testing
// They should be caught by the compiler or runtime

console.log("Error scenarios test file generated");
console.log("Note: These functions contain intentional errors for testing purposes");
)";
        
        saveTestFile("error_scenarios.ts", errorScenarioTest);
        std::cout << "Generated error scenarios test" << std::endl;
    }
    
    void saveTestFile(const std::string& filename, const std::string& content) {
        std::ofstream file(filename);
        if (file.is_open()) {
            file << content;
            file.close();
            std::cout << "Generated: " << filename << std::endl;
        }
    }
};

int main() {
    try {
        ErrorHandlingTestingSuite suite;
        suite.runComprehensiveTesting();
        return 0;
    } catch (const std::exception& e) {
        std::cerr << "Error: " << e.what() << std::endl;
        return 1;
    }
}